Traceback (most recent call last):
  File "Integration.py", line 23, in <module>
    RNA_data = datadict['RNA_data']
KeyError: 'RNA_data'
Traceback (most recent call last):
  File "Integration.py", line 23, in <module>
    RNA_data = datadict['RNA_data']
KeyError: 'RNA_data'
Slc17a7
Nov
Cux2
Rorb
Sulf2
Pcp4
Ctgf
Gad1
Pvalb
Sst
Npy
Vip
Stx1a
Kcna1
Galnt14
Rgs12
Cpne9
Pcdha3
Pcsk2
Slc50a1
Whrn
Kctd6
Sirt3
Zdhhc24
Gpx3
Apod
Pcp4l1
Rab3b
Egr2
Cnp
Lxn
Lhx6
Gabrg1
Mmp16
Ngb
Kit
Snrpb2
Cygb
Cnot6l
Pde11a
Npy2r
Sv2b
Col14a1
Alkbh5
Tacstd2
Rfc2
Pcdhb15
Gria3
Ccar2
S100a16
Ptpn2
Ak1
Lman1l
Chchd3
Cryab
Pcdhb9
Cdca7
Chat
Dusp6
Cbln2
Pcp4
Sirt2
Ina
Wsb2
Znrd1
Mt2
Pcdhac1
Rac1
Myo1c
Npy
Snurf
Msmo1
Akr1e1
Asb11
Cd9
Gstm6
Prdx4
Dgkb
Ak5
Neurod6
A830018L16Rik
Pcdhga8
Mrap2
Trappc2l
Sc5d
Pfkl
Otof
Garnl3
Palmd
Plk2
Sdcbp
Pcdhga5
Fxyd7
Bglap3
Mettl3
Ddit4l
Gmppa
Mgp
Pdyn
Skil
Cpne2
Qpct
Tmbim6
Col25a1
Chrm2
Inhba
Npas1
Ube2e3
Mrps5
Tsc22d1
Pdlim3
Pllp
